Workbook

Sheet Tong_hop
A1: DANH MỤC ĐỊA ĐIỂM PHƯỜNG BÌNH ĐỊNH, TỈNH GIA LAI
A2: Phạm vi: toàn bộ phường Bình Định mới = phường Bình Định cũ + xã Nhơn Khánh cũ + xã Nhơn Phúc cũ. Rà soát đến 27/08/2026. Dữ liệu gồm điểm công khai có thể nhận diện/xác minh; cơ sở nhỏ chưa có dấu vết số vẫn có thể chưa xuất hiện.
A4: Tổng điểm công khai đã lập danh mục | C4: Di tích lịch sử cấp tỉnh đã xếp hạng | E4: Điểm kiểm kê di tích 2026 | G4: Trường công lập trên địa bàn
A5: =COUNTA(Danh_sach_chi_tiet!$D:$D)-1 -> 165 | C5: =COUNTIF(Danh_sach_chi_tiet!$O:$O,"*xếp hạng di tích lịch sử cấp tỉnh*") -> 2 | E5: =COUNTIF(Danh_sach_chi_tiet!$O:$O,"*Kiểm kê 2026*") -> 6 | G5: 10
A8: Nhóm | B8: Số điểm | C8: Có GPS số | D8: Có điện thoại | E8: Mức A | F8: Mức B | G8: Mức C | H8: Có hồ sơ di tích
A9: Di tích lịch sử / khảo cổ | B9: =COUNTIF(Danh_sach_chi_tiet!$B:$B,A9) -> 8 | C9: =COUNTIFS(Danh_sach_chi_tiet!$B:$B,A9,Danh_sach_chi_tiet!$H:$H,">0") -> 1 | D9: =COUNTIFS(Danh_sach_chi_tiet!$B:$B,A9,Danh_sach_chi_tiet!$K:$K,"<>") -> 0 | E9: =COUNTIFS(Danh_sach_chi_tiet!$B:$B,A9,Danh_sach_chi_tiet!$R:$R,"A") -> 8 | F9: =COUNTIFS(Danh_sach_chi_tiet!$B:$B,A9,Danh_sach_chi_tiet!$R:$R,"B") -> 0 | G9: =COUNTIFS(Danh_sach_chi_tiet!$B:$B,A9,Danh_sach_chi_tiet!$R:$R,"C") -> 0 | H9: =COUNTIFS(Danh_sach_chi_tiet!$B:$B,A9,Danh_sach_chi_tiet!$O:$O,"<>") -> 8
A10: Văn hóa / du lịch / tâm linh | B10: =COUNTIF(Danh_sach_chi_tiet!$B:$B,A10) -> 21 | C10: =COUNTIFS(Danh_sach_chi_tiet!$B:$B,A10,Danh_sach_chi_tiet!$H:$H,">0") -> 11 | D10: =COUNTIFS(Danh_sach_chi_tiet!$B:$B,A10,Danh_sach_chi_tiet!$K:$K,"<>") -> 3 | E10: =COUNTIFS(Danh_sach_chi_tiet!$B:$B,A10,Danh_sach_chi_tiet!$R:$R,"A") -> 1 | F10: =COUNTIFS(Danh_sach_chi_tiet!$B:$B,A10,Danh_sach_chi_tiet!$R:$R,"B") -> 18 | G10: =COUNTIFS(Danh_sach_chi_tiet!$B:$B,A10,Danh_sach_chi_tiet!$R:$R,"C") -> 2 | H10: =COUNTIFS(Danh_sach_chi_tiet!$B:$B,A10,Danh_sach_chi_tiet!$O:$O,"<>") -> 0
A11: Lưu trú du lịch | B11: =COUNTIF(Danh_sach_chi_tiet!$B:$B,A11) -> 8 | C11: =COUNTIFS(Danh_sach_chi_tiet!$B:$B,A11,Danh_sach_chi_tiet!$H:$H,">0") -> 4 | D11: =COUNTIFS(Danh_sach_chi_tiet!$B:$B,A11,Danh_sach_chi_tiet!$K:$K,"<>") -> 7 | E11: =COUNTIFS(Danh_sach_chi_tiet!$B:$B,A11,Danh_sach_chi_tiet!$R:$R,"A") -> 2 | F11: =COUNTIFS(Danh_sach_chi_tiet!$B:$B,A11,Danh_sach_chi_tiet!$R:$R,"B") -> 5 | G11: =COUNTIFS(Danh_sach_chi_tiet!$B:$B,A11,Danh_sach_chi_tiet!$R:$R,"C") -> 1 | H11: =COUNTIFS(Danh_sach_chi_tiet!$B:$B,A11,Danh_sach_chi_tiet!$O:$O,"<>") -> 0
A12: Ẩm thực / nhà hàng / cafe | B12: =COUNTIF(Danh_sach_chi_tiet!$B:$B,A12) -> 29 | C12: =COUNTIFS(Danh_sach_chi_tiet!$B:$B,A12,Danh_sach_chi_tiet!$H:$H,">0") -> 7 | D12: =COUNTIFS(Danh_sach_chi_tiet!$B:$B,A12,Danh_sach_chi_tiet!$K:$K,"<>") -> 19 | E12: =COUNTIFS(Danh_sach_chi_tiet!$B:$B,A12,Danh_sach_chi_tiet!$R:$R,"A") -> 2 | F12: =COUNTIFS(Danh_sach_chi_tiet!$B:$B,A12,Danh_sach_chi_tiet!$R:$R,"B") -> 27 | G12: =COUNTIFS(Danh_sach_chi_tiet!$B:$B,A12,Danh_sach_chi_tiet!$R:$R,"C") -> 0 | H12: =COUNTIFS(Danh_sach_chi_tiet!$B:$B,A12,Danh_sach_chi_tiet!$O:$O,"<>") -> 0
A13: Vui chơi / thể thao | B13: =COUNTIF(Danh_sach_chi_tiet!$B:$B,A13) -> 16 | C13: =COUNTIFS(Danh_sach_chi_tiet!$B:$B,A13,Danh_sach_chi_tiet!$H:$H,">0") -> 10 | D13: =COUNTIFS(Danh_sach_chi_tiet!$B:$B,A13,Danh_sach_chi_tiet!$K:$K,"<>") -> 9 | E13: =COUNTIFS(Danh_sach_chi_tiet!$B:$B,A13,Danh_sach_chi_tiet!$R:$R,"A") -> 1 | F13: =COUNTIFS(Danh_sach_chi_tiet!$B:$B,A13,Danh_sach_chi_tiet!$R:$R,"B") -> 14 | G13: =COUNTIFS(Danh_sach_chi_tiet!$B:$B,A13,Danh_sach_chi_tiet!$R:$R,"C") -> 1 | H13: =COUNTIFS(Danh_sach_chi_tiet!$B:$B,A13,Danh_sach_chi_tiet!$O:$O,"<>") -> 0
A14: Y tế / chăm sóc sức khỏe | B14: =COUNTIF(Danh_sach_chi_tiet!$B:$B,A14) -> 13 | C14: =COUNTIFS(Danh_sach_chi_tiet!$B:$B,A14,Danh_sach_chi_tiet!$H:$H,">0") -> 3 | D14: =COUNTIFS(Danh_sach_chi_tiet!$B:$B,A14,Danh_sach_chi_tiet!$K:$K,"<>") -> 8 | E14: =COUNTIFS(Danh_sach_chi_tiet!$B:$B,A14,Danh_sach_chi_tiet!$R:$R,"A") -> 1 | F14: =COUNTIFS(Danh_sach_chi_tiet!$B:$B,A14,Danh_sach_chi_tiet!$R:$R,"B") -> 12 | G14: =COUNTIFS(Danh_sach_chi_tiet!$B:$B,A14,Danh_sach_chi_tiet!$R:$R,"C") -> 0 | H14: =COUNTIFS(Danh_sach_chi_tiet!$B:$B,A14,Danh_sach_chi_tiet!$O:$O,"<>") -> 0
A15: Ngân hàng / ATM | B15: =COUNTIF(Danh_sach_chi_tiet!$B:$B,A15) -> 24 | C15: =COUNTIFS(Danh_sach_chi_tiet!$B:$B,A15,Danh_sach_chi_tiet!$H:$H,">0") -> 3 | D15: =COUNTIFS(Danh_sach_chi_tiet!$B:$B,A15,Danh_sach_chi_tiet!$K:$K,"<>") -> 8 | E15: =COUNTIFS(Danh_sach_chi_tiet!$B:$B,A15,Danh_sach_chi_tiet!$R:$R,"A") -> 5 | F15: =COUNTIFS(Danh_sach_chi_tiet!$B:$B,A15,Danh_sach_chi_tiet!$R:$R,"B") -> 17 | G15: =COUNTIFS(Danh_sach_chi_tiet!$B:$B,A15,Danh_sach_chi_tiet!$R:$R,"C") -> 2 | H15: =COUNTIFS(Danh_sach_chi_tiet!$B:$B,A15,Danh_sach_chi_tiet!$O:$O,"<>") -> 0
A16: Mua sắm / chợ / siêu thị | B16: =COUNTIF(Danh_sach_chi_tiet!$B:$B,A16) -> 8 | C16: =COUNTIFS(Danh_sach_chi_tiet!$B:$B,A16,Danh_sach_chi_tiet!$H:$H,">0") -> 6 | D16: =COUNTIFS(Danh_sach_chi_tiet!$B:$B,A16,Danh_sach_chi_tiet!$K:$K,"<>") -> 4 | E16: =COUNTIFS(Danh_sach_chi_tiet!$B:$B,A16,Danh_sach_chi_tiet!$R:$R,"A") -> 0 | F16: =COUNTIFS(Danh_sach_chi_tiet!$B:$B,A16,Danh_sach_chi_tiet!$R:$R,"B") -> 8 | G16: =COUNTIFS(Danh_sach_chi_tiet!$B:$B,A16,Danh_sach_chi_tiet!$R:$R,"C") -> 0 | H16: =COUNTIFS(Danh_sach_chi_tiet!$B:$B,A16,Danh_sach_chi_tiet!$O:$O,"<>") -> 0
A17: Bưu chính / viễn thông / điện / nhiên liệu | B17: =COUNTIF(Danh_sach_chi_tiet!$B:$B,A17) -> 6 | C17: =COUNTIFS(Danh_sach_chi_tiet!$B:$B,A17,Danh_sach_chi_tiet!$H:$H,">0") -> 2 | D17: =COUNTIFS(Danh_sach_chi_tiet!$B:$B,A17,Danh_sach_chi_tiet!$K:$K,"<>") -> 6 | E17: =COUNTIFS(Danh_sach_chi_tiet!$B:$B,A17,Danh_sach_chi_tiet!$R:$R,"A") -> 0 | F17: =COUNTIFS(Danh_sach_chi_tiet!$B:$B,A17,Danh_sach_chi_tiet!$R:$R,"B") -> 6 | G17: =COUNTIFS(Danh_sach_chi_tiet!$B:$B,A17,Danh_sach_chi_tiet!$R:$R,"C") -> 0 | H17: =COUNTIFS(Danh_sach_chi_tiet!$B:$B,A17,Danh_sach_chi_tiet!$O:$O,"<>") -> 0
A18: Hành chính / công an / PCCC | B18: =COUNTIF(Danh_sach_chi_tiet!$B:$B,A18) -> 13 | C18: =COUNTIFS(Danh_sach_chi_tiet!$B:$B,A18,Danh_sach_chi_tiet!$H:$H,">0") -> 3 | D18: =COUNTIFS(Danh_sach_chi_tiet!$B:$B,A18,Danh_sach_chi_tiet!$K:$K,"<>") -> 2 | E18: =COUNTIFS(Danh_sach_chi_tiet!$B:$B,A18,Danh_sach_chi_tiet!$R:$R,"A") -> 9 | F18: =COUNTIFS(Danh_sach_chi_tiet!$B:$B,A18,Danh_sach_chi_tiet!$R:$R,"B") -> 2 | G18: =COUNTIFS(Danh_sach_chi_tiet!$B:$B,A18,Danh_sach_chi_tiet!$R:$R,"C") -> 2 | H18: =COUNTIFS(Danh_sach_chi_tiet!$B:$B,A18,Danh_sach_chi_tiet!$O:$O,"<>") -> 0
A19: Giáo dục | B19: =COUNTIF(Danh_sach_chi_tiet!$B:$B,A19) -> 19 | C19: =COUNTIFS(Danh_sach_chi_tiet!$B:$B,A19,Danh_sach_chi_tiet!$H:$H,">0") -> 7 | D19: =COUNTIFS(Danh_sach_chi_tiet!$B:$B,A19,Danh_sach_chi_tiet!$K:$K,"<>") -> 8 | E19: =COUNTIFS(Danh_sach_chi_tiet!$B:$B,A19,Danh_sach_chi_tiet!$R:$R,"A") -> 11 | F19: =COUNTIFS(Danh_sach_chi_tiet!$B:$B,A19,Danh_sach_chi_tiet!$R:$R,"B") -> 8 | G19: =COUNTIFS(Danh_sach_chi_tiet!$B:$B,A19,Danh_sach_chi_tiet!$R:$R,"C") -> 0 | H19: =COUNTIFS(Danh_sach_chi_tiet!$B:$B,A19,Danh_sach_chi_tiet!$O:$O,"<>") -> 0
A20: TỔNG CỘNG | B20: =SUM(B9:B19) -> 165 | C20: =SUM(C9:C19) -> 57 | D20: =SUM(D9:D19) -> 74 | E20: =SUM(E9:E19) -> 40 | F20: =SUM(F9:F19) -> 117 | G20: =SUM(G9:G19) -> 8 | H20: =SUM(H9:H19) -> 8

Sheet Danh_sach_chi_tiet
A1: STT | B1: Nhóm | C1: Phân nhóm | D1: Tên địa điểm | E1: Địa chỉ | F1: Khu vực cũ | G1: Plus Code | H1: Latitude | I1: Longitude | J1: Phương pháp tọa độ | K1: Điện thoại | L1: Website/Email | M1: Giờ hoạt động | N1: Từ khóa / giá trị | O1: Tình trạng pháp lý di tích | P1: Ghi chú | Q1: Căn cứ thuộc ranh giới | R1: Mức xác minh | S1: Nguồn chính | T1: Nguồn đối chiếu | U1: Google Maps | V1: Ngày rà soát | W1: Cần kiểm tra bổ sung
A2: 1 | B2: Di tích lịch sử / khảo cổ | C2: Địa điểm kiểm kê lịch sử | D2: Cầu Phụ Ngọc | E2: Cầu Phụ Ngọc, phường Bình Định, tỉnh Gia Lai | F2: Nhơn Khánh / Nhơn Phúc | J2: Chưa có tọa độ số công khai - để link bản đồ để xác minh | N2: lịch sử cách mạng; giao thông | O2: Kiểm kê 2026 theo QĐ 529/QĐ-UBND; đề xuất xếp hạng cấp tỉnh giai đoạn 2030-2035 | P2: Địa điểm gắn với hoạt động đấu tranh chính trị, quân sự; được đưa vào danh mục kiểm kê di tích năm 2026. | Q2: Địa chỉ/điểm bản đồ thuộc phường Bình Định cũ, Nhơn Khánh cũ hoặc Nhơn Phúc cũ - ba đơn vị hợp nhất thành phường Bình Định mới. | R2: A | S2: https://congbao.gialai.gov.vn/congbao/congbao.nsf/70E7DA9FCA87F07B88258D96001301F5/$file/529_signed.pdf | T2: https://tinhthanhvn.com/bando/gia-lai/phuong-binh-dinh | U2: https://www.google.com/maps/search/?api=1&query_place_id=ChIJM0suonk9bzERg6qhlqobluY | V2: 27/08/2026
A3: 2 | B3: Di tích lịch sử / khảo cổ | C3: Lịch sử - kiến trúc | D3: Chùa Ngũ bang Hội quán (An Thái) | E3: Thôn An Thái, phường Bình Định, tỉnh Gia Lai | F3: Nhơn Phúc | J3: Chưa có tọa độ số công khai - để link bản đồ để xác minh | N3: lịch sử; kiến trúc; hội quán; Lễ hội Đổ Giàn; du lịch văn hóa | O3: Kiểm kê 2026 theo QĐ 529/QĐ-UBND; đề xuất xếp hạng cấp tỉnh giai đoạn 2030-2035 | P3: Công trình hội quán/chùa của cộng đồng người Hoa - Việt tại An Thái, phản ánh giao lưu văn hóa thế kỷ XIX và gắn với không gian Lễ hội Đổ Giàn. | Q3: Địa chỉ/điểm bản đồ thuộc phường Bình Định cũ, Nhơn Khánh cũ hoặc Nhơn Phúc cũ - ba đơn vị hợp nhất thành phường Bình Định mới. | R3: A | S3: https://congbao.gialai.gov.vn/congbao/congbao.nsf/70E7DA9FCA87F07B88258D96001301F5/$file/529_signed.pdf | T3: https://baovanhoa.vn/van-hoa/toa-dam-khoi-phuc-le-hoi-do-gian-an-thai-101273.html | U3: https://www.google.com/maps/search/?api=1&query=Ch%C3%B9a%20Ng%C5%A9%20bang%20H%E1%BB%99i%20qu%C3%A1n%20%28An%20Th%C3%A1i%29%2C%20Th%C3%B4n%20An%20Th%C3%A1i%2C%20ph%C6%B0%E1%BB%9Dng%20B%C3%ACnh%20%C4%90%E1%BB%8Bnh%2C%20t%E1%BB%89nh%20Gia%20Lai | V3: 27/08/2026
A4: 3 | B4: Di tích lịch sử / khảo cổ | C4: Di tích lịch sử | D4: Cột cờ thành Bình Định xưa | E4: V4M5+6CR, phường Bình Định, tỉnh Gia Lai | F4: Phường Bình Định cũ | G4: V4M5+6CR | H4: 13.883112 | I4: 109.10852 | J4: Giải mã Plus Code công khai V4M5+6CR | N4: di tích lịch sử; điểm tham quan; Cột cờ thành Bình Định | O4: Đã xếp hạng di tích lịch sử cấp tỉnh — QĐ 336/QĐ-UB ngày 20/05/2005 | P4: Di tích lịch sử Cột cờ thành Bình Định; được xếp hạng cấp tỉnh năm 2005 và là một điểm văn hóa - tham quan của khu vực An Nhơn cũ. | Q4: Địa chỉ/điểm bản đồ thuộc phường Bình Định cũ, Nhơn Khánh cũ hoặc Nhơn Phúc cũ - ba đơn vị hợp nhất thành phường Bình Định mới. | R4: A | S4: https://binhdinh.gov.vn/upload/2005340/20231212/4420_qd_2023_72af7.pdf | T4: https://baogialai.com.vn/an-nhon-bao-ton-di-san-van-hoa-gan-voi-phat-trien-du-lich-post361692.html | U4: https://www.google.com/maps/search/?api=1&query_place_id=ChIJAyUuOQAVbzER3m0lew4CZug | V4: 27/08/2026
A5: 4 | B5: Di tích lịch sử / khảo cổ | C5: Di tích lịch sử | D5: Địa điểm nhà thầy Trương Văn Hiến | E5: Thôn Thắng Công, phường Bình Định, tỉnh Gia Lai (xã Nhơn Phúc cũ) | F5: Nhơn Phúc | J5: Chưa có tọa độ số công khai - để link bản đồ để xác minh | N5: di tích lịch sử; Tây Sơn; giáo dục truyền thống; điểm tham quan | O5: Đã xếp hạng di tích lịch sử cấp tỉnh — QĐ 709/QĐ-UBND ngày 07/03/2019 | P5: Nơi được cho là nhà của thầy Trương Văn Hiến, nơi ba anh em Tây Sơn từng học. Khu vực còn dấu nền móng cũ và giếng đá ong; đã có chủ trương xây dựng Nhà tưởng niệm. | Q5: Địa chỉ/điểm bản đồ thuộc phường Bình Định cũ, Nhơn Khánh cũ hoặc Nhơn Phúc cũ - ba đơn vị hợp nhất thành phường Bình Định mới. | R5: A | S5: https://binhdinh.gov.vn/upload/2005340/20231212/4420_qd_2023_72af7.pdf | T5: https://baogialai.com.vn/tuong-nho-ton-vinh-thay-giao-hien-post423886.html | U5: https://www.google.com/maps/search/?api=1&query=%C4%90%E1%BB%8Ba%20%C4%91i%E1%BB%83m%20nh%C3%A0%20th%E1%BA%A7y%20Tr%C6%B0%C6%A1ng%20V%C4%83n%20Hi%E1%BA%BFn%2C%20Th%C3%B4n%20Th%E1%BA%AFng%20C%C3%B4ng%2C%20ph%C6%B0%E1%BB%9Dng%20B%C3%ACnh%20%C4%90%E1%BB%8Bnh%2C%20t%E1%BB%89nh%20Gia%20Lai%20%28x%C3%A3%20Nh%C6%A1n%20Ph%C3%BAc%20c%C5%A9%29 | V5: 27/08/2026 | W5: Cần khảo sát GPS tại cổng/khuôn viên di tích vì nguồn công khai chưa cho tọa độ số chính xác.
A6: 5 | B6: Di tích lịch sử / khảo cổ | C6: Phế tích khảo cổ Chăm | D6: Phế tích tháp An Hòa | E6: Thôn An Hòa, phường Bình Định, tỉnh Gia Lai; khu vực ven đường 636 | F6: Nhơn Khánh | J6: Chưa có tọa độ số công khai - để link bản đồ để xác minh | N6: khảo cổ; Champa; gò tháp Gãy; Tây Hạ Miếu | O6: Kiểm kê 2026 theo QĐ 529/QĐ-UBND; đề xuất xếp hạng cấp tỉnh giai đoạn 2030-2035 | P6: Phế tích tháp Chăm ở An Hòa, dân gian còn gọi khu vực gò tháp Gãy/Tây Hạ Miếu; thuộc danh mục kiểm kê di tích năm 2026. | Q6: Địa chỉ/điểm bản đồ thuộc phường Bình Định cũ, Nhơn Khánh cũ hoặc Nhơn Phúc cũ - ba đơn vị hợp nhất thành phường Bình Định mới. | R6: A | S6: https://congbao.gialai.gov.vn/congbao/congbao.nsf/70E7DA9FCA87F07B88258D96001301F5/$file/529_signed.pdf | T6: https://tinhthanhvn.com/bando/gia-lai/phuong-binh-dinh | U6: https://www.google.com/maps/search/?api=1&query=Ph%E1%BA%BF%20t%C3%ADch%20th%C3%A1p%20An%20H%C3%B2a%2C%20Th%C3%B4n%20An%20H%C3%B2a%2C%20ph%C6%B0%E1%BB%9Dng%20B%C3%ACnh%20%C4%90%E1%BB%8Bnh%2C%20t%E1%BB%89nh%20Gia%20Lai%3B%20khu%20v%E1%BB%B1c%20ven%20%C4%91%C6%B0%E1%BB%9Dng%20636 | V6: 27/08/2026
A7: 6 | B7: Di tích lịch sử / khảo cổ | C7: Phế tích khảo cổ Chăm | D7: Phế tích tháp Thông Hòa | E7: Thôn Thông Hòa, phường Bình Định, tỉnh Gia Lai | F7: Nhơn Khánh | J7: Chưa có tọa độ số công khai - để link bản đồ để xác minh | N7: khảo cổ; Champa; phế tích tháp Chăm | O7: Kiểm kê 2026 theo QĐ 529/QĐ-UBND; đề xuất xếp hạng cấp tỉnh giai đoạn 2030-2035 | P7: Phế tích kiến trúc tháp Chăm tại thôn Thông Hòa, còn dấu vết vật liệu/nền móng; thuộc danh mục kiểm kê di tích năm 2026. | Q7: Địa chỉ/điểm bản đồ thuộc phường Bình Định cũ, Nhơn Khánh cũ hoặc Nhơn Phúc cũ - ba đơn vị hợp nhất thành phường Bình Định mới. | R7: A | S7: https://congbao.gialai.gov.vn/congbao/congbao.nsf/70E7DA9FCA87F07B88258D96001301F5/$file/529_signed.pdf | T7: https://tinhthanhvn.com/bando/gia-lai/phuong-binh-dinh | U7: https://www.google.com/maps/search/?api=1&query=Ph%E1%BA%BF%20t%C3%ADch%20th%C3%A1p%20Th%C3%B4ng%20H%C3%B2a%2C%20Th%C3%B4n%20Th%C3%B4ng%20H%C3%B2a%2C%20ph%C6%B0%E1%BB%9Dng%20B%C3%ACnh%20%C4%90%E1%BB%8Bnh%2C%20t%E1%BB%89nh%20Gia%20Lai | V7: 27/08/2026
A8: 7 | B8: Di tích lịch sử / khảo cổ | C8: Thể thao | D8: Sân vận động thị xã An Nhơn | E8: 84 Lê Hồng Phong, Bình Định, Gia Lai | F8: Bình Định cũ | J8: Chưa xác minh GPS số; dùng liên kết bản đồ | N8: di tích lịch sử; công trình thể thao; sự kiện 03/09/1945 | O8: Kiểm kê 2026 theo QĐ 529/QĐ-UBND; đề xuất xếp hạng di tích cấp tỉnh giai đoạn 2030-2035 | P8: Sân vận động Bình Định (Sân vận động thị xã An Nhơn) là địa điểm lịch sử gắn với cuộc mít-tinh ngày 03/09/1945; nằm trong danh mục kiểm kê di tích năm 2026. | Q8: Địa chỉ hiện tại được ghi là Bình Định, Gia Lai; đối chiếu với phạm vi hợp nhất 3 đơn vị cũ. | R8: A | S8: https://congbao.gialai.gov.vn/congbao/congbao.nsf/70E7DA9FCA87F07B88258D96001301F5/$file/529_signed.pdf | T8: https://tinhthanhvn.com/bando/gia-lai/phuong-binh-dinh | U8: https://www.google.com/maps/search/?api=1&query_place_id=ChIJGZ9j5xw-bzERbZ7vFj3z438 | V8: 27/08/2026
A9: 8 | B9: Di tích lịch sử / khảo cổ | C9: Địa điểm kiểm kê lịch sử | D9: Từ đường bên ngoại vua Duy Tân | E9: Khu vực Kim Châu, phường Bình Định, tỉnh Gia Lai | F9: Phường Bình Định cũ | J9: Chưa có tọa độ số công khai - để link bản đồ để xác minh | N9: lịch sử; dòng họ; vua Duy Tân | O9: Kiểm kê 2026 theo QĐ 529/QĐ-UBND; đề xuất xếp hạng cấp tỉnh giai đoạn 2030-2035 | P9: Địa điểm lịch sử tại khu vực Kim Châu được đưa vào danh mục kiểm kê di tích của tỉnh năm 2026. | Q9: Địa chỉ/điểm bản đồ thuộc phường Bình Định cũ, Nhơn Khánh cũ hoặc Nhơn Phúc cũ - ba đơn vị hợp nhất thành phường Bình Định mới. | R9: A | S9: https://congbao.gialai.gov.vn/congbao/congbao.nsf/70E7DA9FCA87F07B88258D96001301F5/$file/529_signed.pdf | T9: https://tinhthanhvn.com/bando/gia-lai/phuong-binh-dinh | U9: https://www.google.com/maps/search/?api=1&query=T%E1%BB%AB%20%C4%91%C6%B0%E1%BB%9Dng%20b%C3%AAn%20ngo%E1%BA%A1i%20vua%20Duy%20T%C3%A2n%2C%20Khu%20v%E1%BB%B1c%20Kim%20Ch%C3%A2u%2C%20ph%C6%B0%E1%BB%9Dng%20B%C3%ACnh%20%C4%90%E1%BB%8Bnh%2C%20t%E1%BB%89nh%20Gia%20Lai | V9: 27/08/2026
A10: 9 | B10: Văn hóa / du lịch / tâm linh | C10: Chùa / hội quán | D10: Chùa An Hòa (Chùa Bà Trước) | E10: Thôn An Thái, phường Bình Định, tỉnh Gia Lai | F10: Nhơn Phúc | J10: Chưa có tọa độ số công khai - để link bản đồ để xác minh | N10: tâm linh; kiến trúc; An Thái; Lễ hội Đổ Giàn | P10: Nguồn văn hóa địa phương ghi cơ sở này hình thành khoảng năm 1760 trong không gian văn hóa An Thái. | Q10: Địa chỉ/điểm bản đồ thuộc phường Bình Định cũ, Nhơn Khánh cũ hoặc Nhơn Phúc cũ - ba đơn vị hợp nhất thành phường Bình Định mới. | R10: B | S10: https://baovanhoa.vn/van-hoa/toa-dam-khoi-phuc-le-hoi-do-gian-an-thai-101273.html | T10: https://tinhthanhvn.com/bando/gia-lai/phuong-binh-dinh | U10: https://www.google.com/maps/search/?api=1&query=Ch%C3%B9a%20An%20H%C3%B2a%20%28Ch%C3%B9a%20B%C3%A0%20Tr%C6%B0%E1%BB%9Bc%29%2C%20Th%C3%B4n%20An%20Th%C3%A1i%2C%20ph%C6%B0%E1%BB%9Dng%20B%C3%ACnh%20%C4%90%E1%BB%8Bnh%2C%20t%E1%BB%89nh%20Gia%20Lai | V10: 27/08/2026
A11: 10 | B11: Văn hóa / du lịch / tâm linh | C11: Chùa / hội quán | D11: Chùa Bà Hỏa (Chùa Bà Sau) | E11: Thôn An Thái, phường Bình Định, tỉnh Gia Lai | F11: Nhơn Phúc | J11: Chưa có tọa độ số công khai - để link bản đồ để xác minh | N11: tâm linh; kiến trúc; An Thái; Lễ hội Đổ Giàn | P11: Nguồn văn hóa địa phương ghi cơ sở này hình thành khoảng năm 1847. | Q11: Địa chỉ/điểm bản đồ thuộc phường Bình Định cũ, Nhơn Khánh cũ hoặc Nhơn Phúc cũ - ba đơn vị hợp nhất thành phường Bình Định mới. | R11: B | S11: https://baovanhoa.vn/van-hoa/toa-dam-khoi-phuc-le-hoi-do-gian-an-thai-101273.html | T11: https://tinhthanhvn.com/bando/gia-lai/phuong-binh-dinh | U11: https://www.google.com/maps/search/?api=1&query=Ch%C3%B9a%20B%C3%A0%20H%E1%BB%8Fa%20%28Ch%C3%B9a%20B%C3%A0%20Sau%29%2C%20Th%C3%B4n%20An%20Th%C3%A1i%2C%20ph%C6%B0%E1%BB%9Dng%20B%C3%ACnh%20%C4%90%E1%BB%8Bnh%2C%20t%E1%BB%89nh%20Gia%20Lai | V11: 27/08/2026
A12: 11 | B12: Văn hóa / du lịch / tâm linh | C12: Chùa | D12: Chùa Huệ Khánh | E12: Thôn An Thái, phường Bình Định, tỉnh Gia Lai | F12: Nhơn Phúc | J12: Chưa có tọa độ số công khai - để link bản đồ để xác minh | K12: 0919088363 | N12: tâm linh; chùa; An Thái | Q12: Địa chỉ/điểm bản đồ thuộc phường Bình Định cũ, Nhơn Khánh cũ hoặc Nhơn Phúc cũ - ba đơn vị hợp nhất thành phường Bình Định mới. | R12: B | S12: https://www.google.com/maps/search/?api=1&query_place_id=ChIJAR3qIuw9bzERD51dugj530Q | T12: https://tinhthanhvn.com/bando/gia-lai/phuong-binh-dinh | U12: https://www.google.com/maps/search/?api=1&query_place_id=ChIJAR3qIuw9bzERD51dugj530Q | V12: 27/08/2026
A13: 12 | B13: Văn hóa / du lịch / tâm linh | C13: Tâm linh | D13: Chùa Khánh Liên | E13: V4M8+VM9, Bình Định, Gia Lai | F13: Bình Định cũ | G13: V4M8+VM9 | H13: 13.884662 | I13: 109.11673 | J13: Quy đổi tâm Plus Code V4M8+VM9 | M13: 06:00-20:00 (theo Maps tại thời điểm rà soát) | Q13: Địa chỉ hiện tại được ghi là Bình Định, Gia Lai; đối chiếu với phạm vi hợp nhất 3 đơn vị cũ. | R13: B | S13: https://www.google.com/maps/search/?api=1&query_place_id=ChIJz0OFATU_bzERgICoBQcHsoA | T13: https://tinhthanhvn.com/bando/gia-lai/phuong-binh-dinh | U13: https://www.google.com/maps/search/?api=1&query_place_id=ChIJz0OFATU_bzERgICoBQcHsoA | V13: 27/08/2026
A14: 13 | B14: Văn hóa / du lịch / tâm linh | C14: Tâm linh | D14: Chùa Nhơn Từ | E14: V2X9+QV8, Bình Định, Gia Lai | F14: Nhơn Phúc | G14: V2X9+QV8 | H14: 13.899413 | I14: 109.0197 | J14: Quy đổi tâm Plus Code V2X9+QV8 | P14: Điểm văn hóa/tâm linh; không đồng nghĩa đã được xếp hạng danh lam thắng cảnh. | Q14: Địa chỉ hiện tại được ghi là Bình Định, Gia Lai; đối chiếu với phạm vi hợp nhất 3 đơn vị cũ. | R14: B | S14: https://www.google.com/maps/search/?api=1&query_place_id=ChIJNcccEl09bzERRTEr0ux9NXU | T14: https://tinhthanhvn.com/bando/gia-lai/phuong-binh-dinh | U14: https://www.google.com/maps/search/?api=1&query_place_id=ChIJNcccEl09bzERRTEr0ux9NXU | V14: 27/08/2026
A15: 14 | B15: Văn hóa / du lịch / tâm linh | C15: Chùa / hội quán | D15: Chùa Ông An Thái | E15: Thôn An Thái, phường Bình Định, tỉnh Gia Lai | F15: Nhơn Phúc | J15: Chưa có tọa độ số công khai - để link bản đồ để xác minh | N15: tâm linh; hội quán; An Thái | P15: Một trong các cơ sở tín ngưỡng lịch sử của cộng đồng An Thái; nguồn văn hóa địa phương ghi hình thành khoảng năm 1919. | Q15: Địa chỉ/điểm bản đồ thuộc phường Bình Định cũ, Nhơn Khánh cũ hoặc Nhơn Phúc cũ - ba đơn vị hợp nhất thành phường Bình Định mới. | R15: B | S15: https://baovanhoa.vn/van-hoa/toa-dam-khoi-phuc-le-hoi-do-gian-an-thai-101273.html | T15: https://tinhthanhvn.com/bando/gia-lai/phuong-binh-dinh | U15: https://www.google.com/maps/search/?api=1&query=Ch%C3%B9a%20%C3%94ng%20An%20Th%C3%A1i%2C%20Th%C3%B4n%20An%20Th%C3%A1i%2C%20ph%C6%B0%E1%BB%9Dng%20B%C3%ACnh%20%C4%90%E1%BB%8Bnh%2C%20t%E1%BB%89nh%20Gia%20Lai | V15: 27/08/2026
A16: 15 | B16: Văn hóa / du lịch / tâm linh | C16: Tâm linh | D16: Chùa Thiên An | E16: V4P6+FMP, Lê Hồng Phong, Bình Định, Gia Lai | F16: Bình Định cũ | G16: V4P6+FMP | H16: 13.886212 | I16: 109.1117 | J16: Quy đổi tâm Plus Code V4P6+FMP | Q16: Địa chỉ hiện tại được ghi là Bình Định, Gia Lai; đối chiếu với phạm vi hợp nhất 3 đơn vị cũ. | R16: B | S16: https://www.google.com/maps/search/?api=1&query_place_id=ChIJ9T_BkR4-bzERtn_WlLi8GgE | T16: https://tinhthanhvn.com/bando/gia-lai/phuong-binh-dinh | U16: https://www.google.com/maps/search/?api=1&query_place_id=ChIJ9T_BkR4-bzERtn_WlLi8GgE | V16: 27/08/2026
A17: 16 | B17: Văn hóa / du lịch / tâm linh | C17: Chùa | D17: Chùa Tịnh Hòa | E17: V3R7+GHJ, Khánh Hòa, phường Bình Định, tỉnh Gia Lai | F17: Nhơn Khánh | G17: V3R7+GHJ | H17: 13.891338 | I17: 109.06389 | J17: Giải mã Plus Code công khai V3R7+GHJ | K17: 0389800176 | N17: tâm linh; chùa | Q17: Địa chỉ/điểm bản đồ thuộc phường Bình Định cũ, Nhơn Khánh cũ hoặc Nhơn Phúc cũ - ba đơn vị hợp nhất thành phường Bình Định mới. | R17: B | S17: https://www.google.com/maps/search/?api=1&query_place_id=ChIJl-z55Ys9bzERk8aJxPzYM7I | T17: https://tinhthanhvn.com/bando/gia-lai/phuong-binh-dinh | U17: https://www.google.com/maps/search/?api=1&query_place_id=ChIJl-z55Ys9bzERk8aJxPzYM7I | V17: 27/08/2026
A18: 17 | B18: Văn hóa / du lịch / tâm linh | C18: Tâm linh | D18: Chùa Trúc Liên | E18: V4P8+2P5, Bình Định, Gia Lai | F18: Bình Định cũ | G18: V4P8+2P5 | H18: 13.885013 | I18: 109.11686 | J18: Quy đổi tâm Plus Code V4P8+2P5 | Q18: Địa chỉ hiện tại được ghi là Bình Định, Gia Lai; đối chiếu với phạm vi hợp nhất 3 đơn vị cũ. | R18: B | S18: https://www.google.com/maps/search/?api=1&query_place_id=ChIJ3YnNnQo_bzEReHa0GsoIZBY | T18: https://tinhthanhvn.com/bando/gia-lai/phuong-binh-dinh | U18: https://www.google.com/maps/search/?api=1&query_place_id=ChIJ3YnNnQo_bzEReHa0GsoIZBY | V18: 27/08/2026
A19: 18 | B19: Văn hóa / du lịch / tâm linh | C19: Đình làng | D19: Đình làng thôn Thông Hòa | E19: V3Q6+VJJ, Đội 9, Nhơn Khánh, phường Bình Định, tỉnh Gia Lai | F19: Nhơn Khánh | G19: V3Q6+VJJ | H19: 13.889712 | I19: 109.06152 | J19: Giải mã Plus Code công khai V3Q6+VJJ | N19: đình làng; văn hóa cộng đồng | Q19: Địa chỉ/điểm bản đồ thuộc phường Bình Định cũ, Nhơn Khánh cũ hoặc Nhơn Phúc cũ - ba đơn vị hợp nhất thành phường Bình Định mới. | R19: B | S19: https://www.google.com/maps/search/?api=1&query_place_id=ChIJy-lGKgA9bzERLue_BuXaXZs | T19: https://tinhthanhvn.com/bando/gia-lai/phuong-binh-dinh | U19: https://www.google.com/maps/search/?api=1&query_place_id=ChIJy-lGKgA9bzERLue_BuXaXZs | V19: 27/08/2026
A20: 19 | B20: Văn hóa / du lịch / tâm linh | C20: Làng nghề / trải nghiệm | D20: Làng nghề bún khô - bánh tráng An Thái | E20: Thôn An Thái, phường Bình Định, tỉnh Gia Lai | F20: Nhơn Phúc | J20: Chưa có tọa độ số công khai - để link bản đồ để xác minh | N20: làng nghề; ẩm thực; du lịch cộng đồng; An Thái | P20: Không gian làng nghề truyền thống An Thái, phù hợp nhóm trải nghiệm văn hóa - ẩm thực; không phải một cơ sở duy nhất. | Q20: Địa chỉ/điểm bản đồ thuộc phường Bình Định cũ, Nhơn Khánh cũ hoặc Nhơn Phúc cũ - ba đơn vị hợp nhất thành phường Bình Định mới. | R20: B | S20: https://baogialai.com.vn/tuong-nho-ton-vinh-thay-giao-hien-post423886.html | T20: https://tinhthanhvn.com/bando/gia-lai/phuong-binh-dinh | U20: https://www.google.com/maps/search/?api=1&query=L%C3%A0ng%20ngh%E1%BB%81%20b%C3%BAn%20kh%C3%B4%20-%20b%C3%A1nh%20tr%C3%A1ng%20An%20Th%C3%A1i%2C%20Th%C3%B4n%20An%20Th%C3%A1i%2C%20ph%C6%B0%E1%BB%9Dng%20B%C3%ACnh%20%C4%90%E1%BB%8Bnh%2C%20t%E1%BB%89nh%20Gia%20Lai | V20: 27/08/2026
A21: 20 | B21: Văn hóa / du lịch / tâm linh | C21: Làng võ / trải nghiệm | D21: Làng võ An Thái | E21: Khu vực An Thái, phường Bình Định, tỉnh Gia Lai | F21: Nhơn Phúc | J21: Chưa có tọa độ số công khai - để link bản đồ để xác minh | N21: võ cổ truyền; du lịch văn hóa; An Thái | P21: Không gian truyền thống võ An Thái; nên khảo sát danh sách võ đường đang hoạt động để lập lớp dữ liệu con. | Q21: Địa chỉ/điểm bản đồ thuộc phường Bình Định cũ, Nhơn Khánh cũ hoặc Nhơn Phúc cũ - ba đơn vị hợp nhất thành phường Bình Định mới. | R21: B | S21: https://baogialai.com.vn/tuong-nho-ton-vinh-thay-giao-hien-post423886.html | T21: https://tinhthanhvn.com/bando/gia-lai/phuong-binh-dinh | U21: https://www.google.com/maps/search/?api=1&query=L%C3%A0ng%20v%C3%B5%20An%20Th%C3%A1i%2C%20Khu%20v%E1%BB%B1c%20An%20Th%C3%A1i%2C%20ph%C6%B0%E1%BB%9Dng%20B%C3%ACnh%20%C4%90%E1%BB%8Bnh%2C%20t%E1%BB%89nh%20Gia%20Lai | V21: 27/08/2026
A22: 21 | B22: Văn hóa / du lịch / tâm linh | C22: Miếu | D22: Miễu Phúc Tân | E22: W256+3XC, phường Bình Định, tỉnh Gia Lai | F22: Nhơn Phúc | G22: W256+3XC | H22: 13.907687 | I22: 109.01239 | J22: Giải mã Plus Code công khai W256+3XC | N22: tín ngưỡng dân gian; miếu | Q22: Địa chỉ/điểm bản đồ thuộc phường Bình Định cũ, Nhơn Khánh cũ hoặc Nhơn Phúc cũ - ba đơn vị hợp nhất thành phường Bình Định mới. | R22: B | S22: https://www.google.com/maps/search/?api=1&query_place_id=ChIJIyZyXrA9bzERPaK1aoWcbkY | T22: https://tinhthanhvn.com/bando/gia-lai/phuong-binh-dinh | U22: https://www.google.com/maps/search/?api=1&query_place_id=ChIJIyZyXrA9bzERPaK1aoWcbkY | V22: 27/08/2026
A23: 22 | B23: Văn hóa / du lịch / tâm linh | C23: Tâm linh | D23: Nhà Thờ Giáo Họ Phụ Ngọc | E23: Đập Phụ Ngọc, Bình Định, Gia Lai | F23: Nhơn Phúc | J23: Chưa xác minh GPS số; dùng liên kết bản đồ | Q23: Địa danh Phụ Ngọc thuộc xã Nhơn Phúc cũ; toàn bộ Nhơn Phúc được nhập vào phường Bình Định theo NQ 1664. | R23: B | S23: https://www.google.com/maps/search/?api=1&query_place_id=ChIJB8NNMns9bzERZ5fEAwDa_w0 | T23: https://tinhthanhvn.com/bando/gia-lai/phuong-binh-dinh | U23: https://www.google.com/maps/search/?api=1&query_place_id=ChIJB8NNMns9bzERZ5fEAwDa_w0 | V23: 27/08/2026
A24: 23 | B24: Văn hóa / du lịch / tâm linh | C24: Tâm linh | D24: Nhà Thờ Giáo Xứ Kim Châu | E24: V4R2+H88, Bình Định, Gia Lai | F24: Bình Định cũ | G24: V4R2+H88 | H24: 13.891412 | I24: 109.10083 | J24: Quy đổi tâm Plus Code V4R2+H88 | K24: 0256 383 5746 | Q24: Địa chỉ hiện tại được ghi là Bình Định, Gia Lai; đối chiếu với phạm vi hợp nhất 3 đơn vị cũ. | R24: B | S24: https://www.google.com/maps/search/?api=1&query_place_id=ChIJT8ZqU_QVbzERt3PUFfz9qhc | T24: https://gpquinhon.org/nghe-thuat-thanh/gioi-thieu-hinh-anh-nha-tho-giao-xu-kim-chau-345.html | U24: https://www.google.com/maps/search/?api=1&query_place_id=ChIJT8ZqU_QVbzERt3PUFfz9qhc | V24: 27/08/2026
A25: 24 | B25: Văn hóa / du lịch / tâm linh | C25: Tâm linh | D25: Nhà thờ Thiên Chúa Giáo Tân Thành (Bình Định) | E25: Bình Định, Gia Lai | F25: Bình Định / khu vực phường mới | J25: Chưa xác minh GPS số; dùng liên kết bản đồ | Q25: Địa chỉ hiện tại được ghi là Bình Định, Gia Lai; đối chiếu với phạm vi hợp nhất 3 đơn vị cũ. | R25: C | S25: https://www.google.com/maps/search/?api=1&query_place_id=ChIJvTj7mHMWbzERt3Qq_xtoKK4 | T25: https://tinhthanhvn.com/bando/gia-lai/phuong-binh-dinh | U25: https://www.google.com/maps/search/?api=1&query_place_id=ChIJvTj7mHMWbzERt3Qq_xtoKK4 | V25: 27/08/2026
A26: 25 | B26: Văn hóa / du lịch / tâm linh | C26: Nhà văn hóa | D26: Nhà văn hóa đa năng Nhơn Phúc | E26: W249+P64, khu vực Nhơn Phúc cũ, phường Bình Định, tỉnh Gia Lai | F26: Nhơn Phúc | G26: W249+P64 | H26: 13.906762 | I26: 109.01808 | J26: Giải mã Plus Code công khai W249+P64 | N26: văn hóa cộng đồng; hội họp | Q26: Địa chỉ/điểm bản đồ thuộc phường Bình Định cũ, Nhơn Khánh cũ hoặc Nhơn Phúc cũ - ba đơn vị hợp nhất thành phường Bình Định mới. | R26: B | S26: https://www.google.com/maps/search/?api=1&query=Nh%C3%A0%20v%C4%83n%20h%C3%B3a%20%C4%91a%20n%C4%83ng%20Nh%C6%A1n%20Ph%C3%BAc%2C%20W249%2BP64%2C%20khu%20v%E1%BB%B1c%20Nh%C6%A1n%20Ph%C3%BAc%20c%C5%A9%2C%20ph%C6%B0%E1%BB%9Dng%20B%C3%ACnh%20%C4%90%E1%BB%8Bnh%2C%20t%E1%BB%89nh%20Gia%20Lai | T26: https://tinhthanhvn.com/bando/gia-lai/phuong-binh-dinh | U26: https://www.google.com/maps/search/?api=1&query=Nh%C3%A0%20v%C4%83n%20h%C3%B3a%20%C4%91a%20n%C4%83ng%20Nh%C6%A1n%20Ph%C3%BAc%2C%20W249%2BP64%2C%20khu%20v%E1%BB%B1c%20Nh%C6%A1n%20Ph%C3%BAc%20c%C5%A9%2C%20ph%C6%B0%E1%BB%9Dng%20B%C3%ACnh%20%C4%90%E1%BB%8Bnh%2C%20t%E1%BB%89nh%20Gia%20Lai | V26: 27/08/2026
A27: 26 | B27: Văn hóa / du lịch / tâm linh | C27: Nhà văn hóa | D27: Nhà Văn hóa xã Nhơn Khánh cũ | E27: Khu vực Nhơn Khánh cũ, phường Bình Định, tỉnh Gia Lai | F27: Nhơn Khánh | J27: Chưa có tọa độ số công khai - để link bản đồ để xác minh | N27: văn hóa cộng đồng; hội họp | P27: Địa điểm vẫn được UBND phường mới sử dụng làm nơi tổ chức lấy ý kiến/công việc cộng đồng sau sắp xếp. | Q27: Địa chỉ/điểm bản đồ thuộc phường Bình Định cũ, Nhơn Khánh cũ hoặc Nhơn Phúc cũ - ba đơn vị hợp nhất thành phường Bình Định mới. | R27: A | S27: https://binhdinh.gialai.gov.vn/tin-tuc/phuong-binh-dinh-to-chuc-hoi-nghi-lay-y-kien-du-thao-de-an-sap-xep-to-chuc-lai-cac-to-dan-pho.html | T27: https://tinhthanhvn.com/bando/gia-lai/phuong-binh-dinh | U27: https://www.google.com/maps/search/?api=1&query=Nh%C3%A0%20V%C4%83n%20h%C3%B3a%20x%C3%A3%20Nh%C6%A1n%20Kh%C3%A1nh%20c%C5%A9%2C%20Khu%20v%E1%BB%B1c%20Nh%C6%A1n%20Kh%C3%A1nh%20c%C5%A9%2C%20ph%C6%B0%E1%BB%9Dng%20B%C3%ACnh%20%C4%90%E1%BB%8Bnh%2C%20t%E1%BB%89nh%20Gia%20Lai | V27: 27/08/2026
A28: 27 | B28: Văn hóa / du lịch / tâm linh | C28: Điểm tham quan đô thị | D28: Phố Chợ An Nhơn | E28: V4R5+4MW, Bình Định, Gia Lai | F28: Bình Định cũ | G28: V4R5+4MW | H28: 13.890363 | I28: 109.1092 | J28: Quy đổi tâm Plus Code V4R5+4MW | P28: Google Maps phân loại “Điểm thu hút khách du lịch”. | Q28: Địa chỉ hiện tại được ghi là Bình Định, Gia Lai; đối chiếu với phạm vi hợp nhất 3 đơn vị cũ. | R28: B | S28: https://www.google.com/maps/search/?api=1&query_place_id=ChIJkddN1dc_bzERlswdPZOWi_s | T28: https://tinhthanhvn.com/bando/gia-lai/phuong-binh-dinh | U28: https://www.google.com/maps/search/?api=1&query_place_id=ChIJkddN1dc_bzERlswdPZOWi_s | V28: 27/08/2026
A29: 28 | B29: Văn hóa / du lịch / tâm linh | C29: Miếu / điểm văn hóa | D29: Tây Hạ Miếu | E29: V3RG+RPJ, phường Bình Định, tỉnh Gia Lai | F29: Nhơn Khánh | G29: V3RG+RPJ | H29: 13.892088 | I29: 109.07677 | J29: Giải mã Plus Code công khai V3RG+RPJ | N29: miếu; tín ngưỡng; gần phế tích tháp An Hòa | P29: Điểm tín ngưỡng trong cùng vùng cảnh quan/khảo cổ An Hòa; cần phân biệt với hồ sơ phế tích tháp An Hòa. | Q29: Địa chỉ/điểm bản đồ thuộc phường Bình Định cũ, Nhơn Khánh cũ hoặc Nhơn Phúc cũ - ba đơn vị hợp nhất thành phường Bình Định mới. | R29: B | S29: https://www.google.com/maps/search/?api=1&query_place_id=ChIJ-cD1OQA9bzER3gc-xOtK6m4 | T29: https://tinhthanhvn.com/bando/gia-lai/phuong-binh-dinh | U29: https://www.google.com/maps/search/?api=1&query_place_id=ChIJ-cD1OQA9bzER3gc-xOtK6m4 | V29: 27/08/2026
A30: 29 | B30: Văn hóa / du lịch / tâm linh | C30: Võ đường / di sản võ | D30: Từ đường cố danh sư võ học Diệp Trường Phát | E30: Khu vực An Thái, phường Bình Định, tỉnh Gia Lai | F30: Nhơn Phúc | J30: Chưa có tọa độ số công khai - để link bản đồ để xác minh | N30: võ cổ truyền; danh sư; An Thái | P30: Điểm gắn với truyền thống võ An Thái và danh sư Diệp Trường Phát; cần bổ sung số nhà/GPS khi khảo sát thực địa. | Q30: Địa chỉ/điểm bản đồ thuộc phường Bình Định cũ, Nhơn Khánh cũ hoặc Nhơn Phúc cũ - ba đơn vị hợp nhất thành phường Bình Định mới. | R30: C | S30: https://baovanhoa.vn/van-hoa/toa-dam-khoi-phuc-le-hoi-do-gian-an-thai-101273.html | T30: https://tinhthanhvn.com/bando/gia-lai/phuong-binh-dinh | U30: https://www.google.com/maps/search/?api=1&query=T%E1%BB%AB%20%C4%91%C6%B0%E1%BB%9Dng%20c%E1%BB%91%20danh%20s%C6%B0%20v%C3%B5%20h%E1%BB%8Dc%20Di%E1%BB%87p%20Tr%C6%B0%E1%BB%9Dng%20Ph%C3%A1t%2C%20Khu%20v%E1%BB%B1c%20An%20Th%C3%A1i%2C%20ph%C6%B0%E1%BB%9Dng%20B%C3%ACnh%20%C4%90%E1%BB%8Bnh%2C%20t%E1%BB%89nh%20Gia%20Lai | V30: 27/08/2026 | W30: Cần xác minh vị trí cổng vào và thông tin liên hệ.
A31: 30 | B31: Lưu trú du lịch | C31: Khách sạn / nhà nghỉ | D31: Hotel - Nhà Nghỉ Gia Lâm 2 | E31: Đường Hồ Sĩ Tạo, Bình Định, Gia Lai | F31: Bình Định cũ | J31: Chưa xác minh GPS số; dùng liên kết bản đồ | K31: 0983 091 009 | Q31: Địa chỉ hiện tại được ghi là Bình Định, Gia Lai; đối chiếu với phạm vi hợp nhất 3 đơn vị cũ. | R31: B | S31: https://www.google.com/maps/search/?api=1&query_place_id=ChIJhV6uoRg-bzERLadUCN1hYMc | T31: https://tinhthanhvn.com/bando/gia-lai/phuong-binh-dinh | U31: https://www.google.com/maps/search/?api=1&query_place_id=ChIJhV6uoRg-bzERLadUCN1hYMc | V31: 27/08/2026
A32: 31 | B32: Lưu trú du lịch | C32: Khách sạn | D32: Khách sạn Century | E32: 02 Phan Đình Phùng, Bình Định, Gia Lai 55250 | F32: Bình Định cũ | H32: 13.884286 | I32: 109.11418 | J32: Tọa độ số từ nguồn đối chiếu | K32: 0708 044 044 | L32: Google Travel; centurypalace.net (nguồn cũ) | P32: Số điện thoại hiện tại theo Google Travel/Maps. Nguồn Sổ Tay Vàng cũ hiển thị số khác. | Q32: Địa chỉ hiện tại được ghi là Bình Định, Gia Lai; đối chiếu với phạm vi hợp nhất 3 đơn vị cũ. | R32: A | S32: https://www.google.com.vn/travel/hotels/entity/ChoI17yi-pjmyOb2ARoNL2cvMTFwcjFtczFkMxAB | T32: https://sotayvang.com/khach-san-century-tt-binh-dinh/ | U32: https://www.google.com/maps/search/?api=1&query_place_id=ChIJ30Hzth8-bzERV55IjzEjzfY | V32: 27/08/2026
A33: 32 | B33: Lưu trú du lịch | C33: Nhà nghỉ | D33: Nhà nghỉ 444 | E33: W248+Q6J, phường Bình Định, tỉnh Gia Lai | F33: Nhơn Phúc | G33: W248+Q6J | H33: 13.906963 | I33: 109.01552 | J33: Giải mã Plus Code công khai W248+Q6J | K33: 0942109409 | N33: nhà nghỉ; lưu trú | Q33: Địa chỉ/điểm bản đồ thuộc phường Bình Định cũ, Nhơn Khánh cũ hoặc Nhơn Phúc cũ - ba đơn vị hợp nhất thành phường Bình Định mới. | R33: B | S33: https://www.google.com/maps/search/?api=1&query_place_id=ChIJo4MuU789bzERTxonaVU4jAw | T33: https://tinhthanhvn.com/bando/gia-lai/phuong-binh-dinh | U33: https://www.google.com/maps/search/?api=1&query_place_id=ChIJo4MuU789bzERTxonaVU4jAw | V33: 27/08/2026
A34: 33 | B34: Lưu trú du lịch | C34: Nhà nghỉ | D34: Nhà Nghỉ An Bình | E34: 51 Hàm Nghi, Bình Định, Gia Lai | F34: Bình Định cũ | J34: Chưa xác minh GPS số; dùng liên kết bản đồ | Q34: Địa chỉ hiện tại được ghi là Bình Định, Gia Lai; đối chiếu với phạm vi hợp nhất 3 đơn vị cũ. | R34: C | S34: https://www.google.com/maps/search/?api=1&query_place_id=ChIJp2pxhfUVbzERFn0g5qDT81g | T34: https://tinhthanhvn.com/bando/gia-lai/phuong-binh-dinh | U34: https://www.google.com/maps/search/?api=1&query_place_id=ChIJp2pxhfUVbzERFn0g5qDT81g | V34: 27/08/2026
A35: 34 | B35: Lưu trú du lịch | C35: Nhà nghỉ | D35: Nhà nghỉ Gia Lâm | E35: V4R8+6F5, QL1A, phường Bình Định, tỉnh Gia Lai | F35: Phường Bình Định cũ | G35: V4R8+6F5 | H35: 13.890512 | I35: 109.11623 | J35: Giải mã Plus Code công khai V4R8+6F5 | K35: 0983110009 | N35: nhà nghỉ; lưu trú | Q35: Địa chỉ/điểm bản đồ thuộc phường Bình Định cũ, Nhơn Khánh cũ hoặc Nhơn Phúc cũ - ba đơn vị hợp nhất thành phường Bình Định mới. | R35: B | S35: https://www.google.com/maps/search/?api=1&query_place_id=ChIJRakpgRg-bzERBGSUsUY1psE | T35: https://tinhthanhvn.com/bando/gia-lai/phuong-binh-dinh | U35: https://www.google.com/maps/search/?api=1&query_place_id=ChIJRakpgRg-bzERBGSUsUY1psE | V35: 27/08/2026
A36: 35 | B36: Lưu trú du lịch | C36: Khách sạn | D36: NiNa Hotel | E36: V4PC+4HC, Bình Định, Gia Lai | F36: Bình Định cũ | G36: V4PC+4HC | H36: 13.885312 | I36: 109.12139 | J36: Quy đổi tâm Plus Code V4PC+4HC | K36: 0917 777 268 | Q36: Địa chỉ hiện tại được ghi là Bình Định, Gia Lai; đối chiếu với phạm vi hợp nhất 3 đơn vị cũ. | R36: B | S36: https://www.google.com/maps/search/?api=1&query_place_id=ChIJe-f0UwY_bzERHt91NyNuOHc | T36: https://tinhthanhvn.com/bando/gia-lai/phuong-binh-dinh | U36: https://www.google.com/maps/search/?api=1&query_place_id=ChIJe-f0UwY_bzERHt91NyNuOHc | V36: 27/08/2026
A37: 36 | B37: Lưu trú du lịch | C37: Khách sạn | D37: One Hotel | E37: 45 Trần Văn Ơn, Bình Định, Gia Lai 55250 | F37: Bình Định cũ | J37: Chưa xác minh GPS số; dùng liên kết bản đồ | K37: 0704 088 088 | Q37: Địa chỉ hiện tại được ghi là Bình Định, Gia Lai; đối chiếu với phạm vi hợp nhất 3 đơn vị cũ. | R37: B | S37: https://www.google.com/maps/search/?api=1&query_place_id=ChIJgycv4a4VbzERKMh-YFjTEPk | T37: https://tinhthanhvn.com/bando/gia-lai/phuong-binh-dinh | U37: https://www.google.com/maps/search/?api=1&query_place_id=ChIJgycv4a4VbzERKMh-YFjTEPk | V37: 27/08/2026
A38: 37 | B38: Lưu trú du lịch | C38: Khách sạn | D38: REX HOTEL AN NHON | E38: 02 Cần Vương, Phường Bình Định, Tỉnh Gia Lai | F38: Bình Định cũ | J38: Chưa xác minh GPS số; dùng liên kết bản đồ | K38: 0256 383 5188; KD: 0788 686 869 | L38: https://rexannhon.vn/ ; rexhotelannhon@gmail.com | M38: 24/24 | P38: Website chính thức của khách sạn xác nhận địa chỉ và liên hệ. | Q38: Địa chỉ hiện tại được ghi là Bình Định, Gia Lai; đối chiếu với phạm vi hợp nhất 3 đơn vị cũ. | R38: A | S38: https://rexannhon.vn/nha-hang-alacarte/ | T38: https://tinhthanhvn.com/bando/gia-lai/phuong-binh-dinh | U38: https://www.google.com/maps/search/?api=1&query_place_id=ChIJPUFBWwAVbzEROJlNjm3xiwg | V38: 27/08/2026
A39: 38 | B39: Ẩm thực / nhà hàng / cafe | C39: Ẩm thực chay | D39: Ẩm Thực Chay Tâm Phúc | E39: Lê Hồng Phong nối dài, Bình Định, Gia Lai | F39: Bình Định cũ | J39: Chưa xác minh GPS số; dùng liên kết bản đồ | K39: 0358 667 696 | M39: 06:00-13:30; 15:30-21:30 | Q39: Địa chỉ hiện tại được ghi là Bình Định, Gia Lai; đối chiếu với phạm vi hợp nhất 3 đơn vị cũ. | R39: B | S39: https://www.google.com/maps/search/?api=1&query_place_id=ChIJSw3nL3s_bzER56X5hgP7ENc | T39: https://tinhthanhvn.com/bando/gia-lai/phuong-binh-dinh | U39: https://www.google.com/maps/search/?api=1&query_place_id=ChIJSw3nL3s_bzER56X5hgP7ENc | V39: 27/08/2026
A40: 39 | B40: Ẩm thực / nhà hàng / cafe | C40: Ẩm thực | D40: Ẩm Thực Sơ Ri Bình Định | E40: V4M7+FVM, Phan Đình Phùng, phường Bình Định, tỉnh Gia Lai | F40: Phường Bình Định cũ | G40: V4M7+FVM | H40: 13.883712 | I40: 109.11467 | J40: Giải mã Plus Code công khai V4M7+FVM | N40: ẩm thực; quán ăn | Q40: Địa chỉ/điểm bản đồ thuộc phường Bình Định cũ, Nhơn Khánh cũ hoặc Nhơn Phúc cũ - ba đơn vị hợp nhất thành phường Bình Định mới. | R40: B | S40: https://www.google.com/maps/search/?api=1&query=%E1%BA%A8m%20Th%E1%BB%B1c%20S%C6%A1%20Ri%20B%C3%ACnh%20%C4%90%E1%BB%8Bnh%2C%20V4M7%2BFVM%2C%20Phan%20%C4%90%C3%ACnh%20Ph%C3%B9ng%2C%20ph%C6%B0%E1%BB%9Dng%20B%C3%ACnh%20%C4%90%E1%BB%8Bnh%2C%20t%E1%BB%89nh%20Gia%20Lai | T40: https://tinhthanhvn.com/bando/gia-lai/phuong-binh-dinh | U40: https://www.google.com/maps/search/?api=1&query=%E1%BA%A8m%20Th%E1%BB%B1c%20S%C6%A1%20Ri%20B%C3%ACnh%20%C4%90%E1%BB%8Bnh%2C%20V4M7%2BFVM%2C%20Phan%20%C4%90%C3%ACnh%20Ph%C3%B9ng%2C%20ph%C6%B0%E1%BB%9Dng%20B%C3%ACnh%20%C4%90%E1%BB%8Bnh%2C%20t%E1%BB%89nh%20Gia%20Lai | V40: 27/08/2026
...

Sheet Di_tich_lich_su
A1: STT | B1: Tên di tích / địa điểm | C1: Loại hình | D1: Địa chỉ | E1: Khu vực cũ | F1: Plus Code | G1: Latitude | H1: Longitude | I1: Tình trạng pháp lý | J1: Giá trị / ghi chú | K1: Nguồn pháp lý | L1: Google Maps
A2: 1 | B2: Cầu Phụ Ngọc | C2: Địa điểm kiểm kê lịch sử | D2: Cầu Phụ Ngọc, phường Bình Định, tỉnh Gia Lai | E2: Nhơn Khánh / Nhơn Phúc | I2: Kiểm kê 2026 theo QĐ 529/QĐ-UBND; đề xuất xếp hạng cấp tỉnh giai đoạn 2030-2035 | J2: Địa điểm gắn với hoạt động đấu tranh chính trị, quân sự; được đưa vào danh mục kiểm kê di tích năm 2026. | K2: https://congbao.gialai.gov.vn/congbao/congbao.nsf/70E7DA9FCA87F07B88258D96001301F5/$file/529_signed.pdf | L2: https://www.google.com/maps/search/?api=1&query_place_id=ChIJM0suonk9bzERg6qhlqobluY
A3: 2 | B3: Chùa Ngũ bang Hội quán (An Thái) | C3: Lịch sử - kiến trúc | D3: Thôn An Thái, phường Bình Định, tỉnh Gia Lai | E3: Nhơn Phúc | I3: Kiểm kê 2026 theo QĐ 529/QĐ-UBND; đề xuất xếp hạng cấp tỉnh giai đoạn 2030-2035 | J3: Công trình hội quán/chùa của cộng đồng người Hoa - Việt tại An Thái, phản ánh giao lưu văn hóa thế kỷ XIX và gắn với không gian Lễ hội Đổ Giàn. | K3: https://congbao.gialai.gov.vn/congbao/congbao.nsf/70E7DA9FCA87F07B88258D96001301F5/$file/529_signed.pdf | L3: https://www.google.com/maps/search/?api=1&query=Ch%C3%B9a%20Ng%C5%A9%20bang%20H%E1%BB%99i%20qu%C3%A1n%20%28An%20Th%C3%A1i%29%2C%20Th%C3%B4n%20An%20Th%C3%A1i%2C%20ph%C6%B0%E1%BB%9Dng%20B%C3%ACnh%20%C4%90%E1%BB%8Bnh%2C%20t%E1%BB%89nh%20Gia%20Lai
A4: 3 | B4: Cột cờ thành Bình Định xưa | C4: Di tích lịch sử | D4: V4M5+6CR, phường Bình Định, tỉnh Gia Lai | E4: Phường Bình Định cũ | F4: V4M5+6CR | G4: 13.883112 | H4: 109.10852 | I4: Đã xếp hạng di tích lịch sử cấp tỉnh — QĐ 336/QĐ-UB ngày 20/05/2005 | J4: Di tích lịch sử Cột cờ thành Bình Định; được xếp hạng cấp tỉnh năm 2005 và là một điểm văn hóa - tham quan của khu vực An Nhơn cũ. | K4: https://binhdinh.gov.vn/upload/2005340/20231212/4420_qd_2023_72af7.pdf | L4: https://www.google.com/maps/search/?api=1&query_place_id=ChIJAyUuOQAVbzER3m0lew4CZug
A5: 4 | B5: Địa điểm nhà thầy Trương Văn Hiến | C5: Di tích lịch sử | D5: Thôn Thắng Công, phường Bình Định, tỉnh Gia Lai (xã Nhơn Phúc cũ) | E5: Nhơn Phúc | I5: Đã xếp hạng di tích lịch sử cấp tỉnh — QĐ 709/QĐ-UBND ngày 07/03/2019 | J5: Nơi được cho là nhà của thầy Trương Văn Hiến, nơi ba anh em Tây Sơn từng học. Khu vực còn dấu nền móng cũ và giếng đá ong; đã có chủ trương xây dựng Nhà tưởng niệm. | K5: https://binhdinh.gov.vn/upload/2005340/20231212/4420_qd_2023_72af7.pdf | L5: https://www.google.com/maps/search/?api=1&query=%C4%90%E1%BB%8Ba%20%C4%91i%E1%BB%83m%20nh%C3%A0%20th%E1%BA%A7y%20Tr%C6%B0%C6%A1ng%20V%C4%83n%20Hi%E1%BA%BFn%2C%20Th%C3%B4n%20Th%E1%BA%AFng%20C%C3%B4ng%2C%20ph%C6%B0%E1%BB%9Dng%20B%C3%ACnh%20%C4%90%E1%BB%8Bnh%2C%20t%E1%BB%89nh%20Gia%20Lai%20%28x%C3%A3%20Nh%C6%A1n%20Ph%C3%BAc%20c%C5%A9%29
A6: 5 | B6: Phế tích tháp An Hòa | C6: Phế tích khảo cổ Chăm | D6: Thôn An Hòa, phường Bình Định, tỉnh Gia Lai; khu vực ven đường 636 | E6: Nhơn Khánh | I6: Kiểm kê 2026 theo QĐ 529/QĐ-UBND; đề xuất xếp hạng cấp tỉnh giai đoạn 2030-2035 | J6: Phế tích tháp Chăm ở An Hòa, dân gian còn gọi khu vực gò tháp Gãy/Tây Hạ Miếu; thuộc danh mục kiểm kê di tích năm 2026. | K6: https://congbao.gialai.gov.vn/congbao/congbao.nsf/70E7DA9FCA87F07B88258D96001301F5/$file/529_signed.pdf | L6: https://www.google.com/maps/search/?api=1&query=Ph%E1%BA%BF%20t%C3%ADch%20th%C3%A1p%20An%20H%C3%B2a%2C%20Th%C3%B4n%20An%20H%C3%B2a%2C%20ph%C6%B0%E1%BB%9Dng%20B%C3%ACnh%20%C4%90%E1%BB%8Bnh%2C%20t%E1%BB%89nh%20Gia%20Lai%3B%20khu%20v%E1%BB%B1c%20ven%20%C4%91%C6%B0%E1%BB%9Dng%20636
A7: 6 | B7: Phế tích tháp Thông Hòa | C7: Phế tích khảo cổ Chăm | D7: Thôn Thông Hòa, phường Bình Định, tỉnh Gia Lai | E7: Nhơn Khánh | I7: Kiểm kê 2026 theo QĐ 529/QĐ-UBND; đề xuất xếp hạng cấp tỉnh giai đoạn 2030-2035 | J7: Phế tích kiến trúc tháp Chăm tại thôn Thông Hòa, còn dấu vết vật liệu/nền móng; thuộc danh mục kiểm kê di tích năm 2026. | K7: https://congbao.gialai.gov.vn/congbao/congbao.nsf/70E7DA9FCA87F07B88258D96001301F5/$file/529_signed.pdf | L7: https://www.google.com/maps/search/?api=1&query=Ph%E1%BA%BF%20t%C3%ADch%20th%C3%A1p%20Th%C3%B4ng%20H%C3%B2a%2C%20Th%C3%B4n%20Th%C3%B4ng%20H%C3%B2a%2C%20ph%C6%B0%E1%BB%9Dng%20B%C3%ACnh%20%C4%90%E1%BB%8Bnh%2C%20t%E1%BB%89nh%20Gia%20Lai
A8: 7 | B8: Sân vận động thị xã An Nhơn | C8: Thể thao | D8: 84 Lê Hồng Phong, Bình Định, Gia Lai | E8: Bình Định cũ | I8: Kiểm kê 2026 theo QĐ 529/QĐ-UBND; đề xuất xếp hạng di tích cấp tỉnh giai đoạn 2030-2035 | J8: Sân vận động Bình Định (Sân vận động thị xã An Nhơn) là địa điểm lịch sử gắn với cuộc mít-tinh ngày 03/09/1945; nằm trong danh mục kiểm kê di tích năm 2026. | K8: https://congbao.gialai.gov.vn/congbao/congbao.nsf/70E7DA9FCA87F07B88258D96001301F5/$file/529_signed.pdf | L8: https://www.google.com/maps/search/?api=1&query_place_id=ChIJGZ9j5xw-bzERbZ7vFj3z438
A9: 8 | B9: Từ đường bên ngoại vua Duy Tân | C9: Địa điểm kiểm kê lịch sử | D9: Khu vực Kim Châu, phường Bình Định, tỉnh Gia Lai | E9: Phường Bình Định cũ | I9: Kiểm kê 2026 theo QĐ 529/QĐ-UBND; đề xuất xếp hạng cấp tỉnh giai đoạn 2030-2035 | J9: Địa điểm lịch sử tại khu vực Kim Châu được đưa vào danh mục kiểm kê di tích của tỉnh năm 2026. | K9: https://congbao.gialai.gov.vn/congbao/congbao.nsf/70E7DA9FCA87F07B88258D96001301F5/$file/529_signed.pdf | L9: https://www.google.com/maps/search/?api=1&query=T%E1%BB%AB%20%C4%91%C6%B0%E1%BB%9Dng%20b%C3%AAn%20ngo%E1%BA%A1i%20vua%20Duy%20T%C3%A2n%2C%20Khu%20v%E1%BB%B1c%20Kim%20Ch%C3%A2u%2C%20ph%C6%B0%E1%BB%9Dng%20B%C3%ACnh%20%C4%90%E1%BB%8Bnh%2C%20t%E1%BB%89nh%20Gia%20Lai

Sheet Ranh_gioi
A1: Nội dung | B1: Thông tin | C1: Nguồn
A2: Phạm vi hành chính | B2: Phường Bình Định mới được thành lập trên cơ sở toàn bộ phường Bình Định cũ, xã Nhơn Khánh cũ và xã Nhơn Phúc cũ; mã đơn vị 21907; diện tích khoảng 25,16 km². | C2: https://tinhthanhvn.com/bando/gia-lai/phuong-binh-dinh
A3: Nguyên tắc lọc | B3: Chỉ giữ điểm có địa chỉ/Plus Code/toạ độ hoặc nguồn hành chính cho thấy thuộc một trong ba đơn vị cũ nêu trên. Không lấy các điểm ở An Nhơn Đông, An Nhơn Bắc, Quy Nhơn hoặc đơn vị khác. | C3: https://tinhthanhvn.com/bando/gia-lai/phuong-binh-dinh
A4: Ranh giới pháp lý | B4: Ba đơn vị cũ được hợp nhất nguyên trạng; vì vậy việc đối chiếu tên thôn/khu vực cũ là một căn cứ quan trọng khi dữ liệu bản đồ chưa có polygon tải trực tiếp. | C4: https://tinhthanhvn.com/bando/gia-lai/phuong-binh-dinh
A5: Trung tâm hành chính | B5: UBND phường Bình Định: 78 Lê Hồng Phong, phường Bình Định, tỉnh Gia Lai. | C5: https://binhdinh.gialai.gov.vn/
A6: Giáo dục công lập 2025-2026 | B6: Toàn phường có 10 trường công lập, 194 nhóm/lớp và 6.730 trẻ, học sinh. | C6: https://binhdinh.gialai.gov.vn/tin-tuc/van-hoa-xa-hoi/phuong-binh-dinh-tong-ket-nam-hoc-2025-2026-trien-khai-nhiem-vu-nam-hoc-2026-2027.html

Sheet Nguon_du_lieu
A1: STT | B1: Vai trò nguồn | C1: URL
A2: 1 | B2: Nguồn đối chiếu ranh giới/thông tin | C2: https://baogialai.com.vn/an-nhon-bao-ton-di-san-van-hoa-gan-voi-phat-trien-du-lich-post361692.html
A3: 2 | B3: Nguồn chính của điểm, Nguồn đối chiếu ranh giới/thông tin | C3: https://baogialai.com.vn/tuong-nho-ton-vinh-thay-giao-hien-post423886.html
A4: 3 | B4: Nguồn chính của điểm, Nguồn đối chiếu ranh giới/thông tin | C4: https://baovanhoa.vn/van-hoa/toa-dam-khoi-phuc-le-hoi-do-gian-an-thai-101273.html
A5: 4 | B5: Nguồn chính của điểm | C5: https://bidv.nganhangs.com/chi-nhanh/binh-dinh/an-nhon/duong-tran-phu/pgd-an-nhon_c43
A6: 5 | B6: Nguồn chính của điểm, Nguồn đối chiếu ranh giới/thông tin | C6: https://binhdinh.gialai.gov.vn/
A7: 6 | B7: Nguồn chính của điểm | C7: https://binhdinh.gialai.gov.vn/tin-tuc/phuong-binh-dinh-to-chuc-hoi-nghi-lay-y-kien-du-thao-de-an-sap-xep-to-chuc-lai-cac-to-dan-pho.html
A8: 7 | B8: Nguồn đối chiếu ranh giới/thông tin | C8: https://binhdinh.gialai.gov.vn/tin-tuc/van-hoa-xa-hoi/phuong-binh-dinh-tong-ket-nam-hoc-2025-2026-trien-khai-nhiem-vu-nam-hoc-2026-2027.html
A9: 8 | B9: Nguồn chính của điểm, Nguồn đối chiếu ranh giới/thông tin | C9: https://binhdinh.gialai.gov.vn/upload/105724/20250923/Copy_of_PHU_LUC_GIAO_39_TRU_SO_LAM_VIEC__CO_SO_HOAT_DONG_SU_NGHIEP_THUOC_UBND_PHUONG_BINH_DINH_QUAN_LY__SU_DUNG_f0503.pdf
A10: 9 | B10: Nguồn chính của điểm | C10: https://binhdinh.gov.vn/upload/2005340/20231212/4420_qd_2023_72af7.pdf
A11: 10 | B11: Nguồn chính của điểm | C11: https://congbao.gialai.gov.vn/congbao/congbao.nsf/70E7DA9FCA87F07B88258D96001301F5/$file/529_signed.pdf
A12: 11 | B12: Nguồn đối chiếu ranh giới/thông tin | C12: https://gialai.hdbank.com.vn/
A13: 12 | B13: Nguồn đối chiếu ranh giới/thông tin | C13: https://gpquinhon.org/nghe-thuat-thanh/gioi-thieu-hinh-anh-nha-tho-giao-xu-kim-chau-345.html
... A193: 192 | B193: Link bản đồ, Nguồn chính của điểm | C193: https://www.google.com/maps/search/?api=1&query_place_id=ChIJz8tDnKc_bzERIOQhwWi6xfM

Sheet Kiem_tra_bo_sung
A1: STT | B1: STT danh mục | C1: Nhóm | D1: Tên địa điểm | E1: Địa chỉ | F1: Nội dung cần kiểm tra | G1: Nguồn chính | H1: Google Maps
A2: 1 | B2: 1 | C2: Di tích lịch sử / khảo cổ | D2: Cầu Phụ Ngọc | E2: Cầu Phụ Ngọc, phường Bình Định, tỉnh Gia Lai | F2: Chưa có GPS số; Chưa có số điện thoại công khai | G2: https://congbao.gialai.gov.vn/congbao/congbao.nsf/70E7DA9FCA87F07B88258D96001301F5/$file/529_signed.pdf | H2: https://www.google.com/maps/search/?api=1&query_place_id=ChIJM0suonk9bzERg6qhlqobluY
A3: 2 | B3: 2 | C3: Di tích lịch sử / khảo cổ | D3: Chùa Ngũ bang Hội quán (An Thái) | E3: Thôn An Thái, phường Bình Định, tỉnh Gia Lai | F3: Chưa có GPS số; Chưa có số điện thoại công khai | G3: https://congbao.gialai.gov.vn/congbao/congbao.nsf/70E7DA9FCA87F07B88258D96001301F5/$file/529_signed.pdf | H3: https://www.google.com/maps/search/?api=1&query=Ch%C3%B9a%20Ng%C5%A9%20bang%20H%E1%BB%99i%20qu%C3%A1n%20%28An%20Th%C3%A1i%29%2C%20Th%C3%B4n%20An%20Th%C3%A1i%2C%20ph%C6%B0%E1%BB%9Dng%20B%C3%ACnh%20%C4%90%E1%BB%8Bnh%2C%20t%E1%BB%89nh%20Gia%20Lai
A4: 3 | B4: 3 | C4: Di tích lịch sử / khảo cổ | D4: Cột cờ thành Bình Định xưa | E4: V4M5+6CR, phường Bình Định, tỉnh Gia Lai | F4: Chưa có số điện thoại công khai | G4: https://binhdinh.gov.vn/upload/2005340/20231212/4420_qd_2023_72af7.pdf | H4: https://www.google.com/maps/search/?api=1&query_place_id=ChIJAyUuOQAVbzER3m0lew4CZug
A5: 4 | B5: 4 | C5: Di tích lịch sử / khảo cổ | D5: Địa điểm nhà thầy Trương Văn Hiến | E5: Thôn Thắng Công, phường Bình Định, tỉnh Gia Lai (xã Nhơn Phúc cũ) | F5: Chưa có GPS số; Chưa có số điện thoại công khai; Cần khảo sát GPS tại cổng/khuôn viên di tích vì nguồn công khai chưa cho tọa độ số chính xác. | G5: https://binhdinh.gov.vn/upload/2005340/20231212/4420_qd_2023_72af7.pdf | H5: https://www.google.com/maps/search/?api=1&query=%C4%90%E1%BB%8Ba%20%C4%91i%E1%BB%83m%20nh%C3%A0%20th%E1%BA%A7y%20Tr%C6%B0%C6%A1ng%20V%C4%83n%20Hi%E1%BA%BFn%2C%20Th%C3%B4n%20Th%E1%BA%AFng%20C%C3%B4ng%2C%20ph%C6%B0%E1%BB%9Dng%20B%C3%ACnh%20%C4%90%E1%BB%8Bnh%2C%20t%E1%BB%89nh%20Gia%20Lai%20%28x%C3%A3%20Nh%C6%A1n%20Ph%C3%BAc%20c%C5%A9%29
A6: 5 | B6: 5 | C6: Di tích lịch sử / khảo cổ | D6: Phế tích tháp An Hòa | E6: Thôn An Hòa, phường Bình Định, tỉnh Gia Lai; khu vực ven đường 636 | F6: Chưa có GPS số; Chưa có số điện thoại công khai | G6: https://congbao.gialai.gov.vn/congbao/congbao.nsf/70E7DA9FCA87F07B88258D96001301F5/$file/529_signed.pdf | H6: https://www.google.com/maps/search/?api=1&query=Ph%E1%BA%BF%20t%C3%ADch%20th%C3%A1p%20An%20H%C3%B2a%2C%20Th%C3%B4n%20An%20H%C3%B2a%2C%20ph%C6%B0%E1%BB%9Dng%20B%C3%ACnh%20%C4%90%E1%BB%8Bnh%2C%20t%E1%BB%89nh%20Gia%20Lai%3B%20khu%20v%E1%BB%B1c%20ven%20%C4%91%C6%B0%E1%BB%9Dng%20636
A7: 6 | B7: 6 | C7: Di tích lịch sử / khảo cổ | D7: Phế tích tháp Thông Hòa | E7: Thôn Thông Hòa, phường Bình Định, tỉnh Gia Lai | F7: Chưa có GPS số; Chưa có số điện thoại công khai | G7: https://congbao.gialai.gov.vn/congbao/congbao.nsf/70E7DA9FCA87F07B88258D96001301F5/$file/529_signed.pdf | H7: https://www.google.com/maps/search/?api=1&query=Ph%E1%BA%BF%20t%C3%ADch%20th%C3%A1p%20Th%C3%B4ng%20H%C3%B2a%2C%20Th%C3%B4n%20Th%C3%B4ng%20H%C3%B2a%2C%20ph%C6%B0%E1%BB%9Dng%20B%C3%ACnh%20%C4%90%E1%BB%8Bnh%2C%20t%E1%BB%89nh%20Gia%20Lai
A8: 7 | B8: 7 | C8: Di tích lịch sử / khảo cổ | D8: Sân vận động thị xã An Nhơn | E8: 84 Lê Hồng Phong, Bình Định, Gia Lai | F8: Chưa có GPS số; Chưa có số điện thoại công khai | G8: https://congbao.gialai.gov.vn/congbao/congbao.nsf/70E7DA9FCA87F07B88258D96001301F5/$file/529_signed.pdf | H8: https://www.google.com/maps/search/?api=1&query_place_id=ChIJGZ9j5xw-bzERbZ7vFj3z438
A9: 8 | B9: 8 | C9: Di tích lịch sử / khảo cổ | D9: Từ đường bên ngoại vua Duy Tân | E9: Khu vực Kim Châu, phường Bình Định, tỉnh Gia Lai | F9: Chưa có GPS số; Chưa có số điện thoại công khai | G9: https://congbao.gialai.gov.vn/congbao/congbao.nsf/70E7DA9FCA87F07B88258D96001301F5/$file/529_signed.pdf | H9: https://www.google.com/maps/search/?api=1&query=T%E1%BB%AB%20%C4%91%C6%B0%E1%BB%9Dng%20b%C3%AAn%20ngo%E1%BA%A1i%20vua%20Duy%20T%C3%A2n%2C%20Khu%20v%E1%BB%B1c%20Kim%20Ch%C3%A2u%2C%20ph%C6%B0%E1%BB%9Dng%20B%C3%ACnh%20%C4%90%E1%BB%8Bnh%2C%20t%E1%BB%89nh%20Gia%20Lai
A10: 9 | B10: 9 | C10: Văn hóa / du lịch / tâm linh | D10: Chùa An Hòa (Chùa Bà Trước) | E10: Thôn An Thái, phường Bình Định, tỉnh Gia Lai | F10: Chưa có GPS số; Chưa có số điện thoại công khai | G10: https://baovanhoa.vn/van-hoa/toa-dam-khoi-phuc-le-hoi-do-gian-an-thai-101273.html | H10: https://www.google.com/maps/search/?api=1&query=Ch%C3%B9a%20An%20H%C3%B2a%20%28Ch%C3%B9a%20B%C3%A0%20Tr%C6%B0%E1%BB%9Bc%29%2C%20Th%C3%B4n%20An%20Th%C3%A1i%2C%20ph%C6%B0%E1%BB%9Dng%20B%C3%ACnh%20%C4%90%E1%BB%8Bnh%2C%20t%E1%BB%89nh%20Gia%20Lai
A11: 10 | B11: 10 | C11: Văn hóa / du lịch / tâm linh | D11: Chùa Bà Hỏa (Chùa Bà Sau) | E11: Thôn An Thái, phường Bình Định, tỉnh Gia Lai | F11: Chưa có GPS số; Chưa có số điện thoại công khai | G11: https://baovanhoa.vn/van-hoa/toa-dam-khoi-phuc-le-hoi-do-gian-an-thai-101273.html | H11: https://www.google.com/maps/search/?api=1&query=Ch%C3%B9a%20B%C3%A0%20H%E1%BB%8Fa%20%28Ch%C3%B9a%20B%C3%A0%20Sau%29%2C%20Th%C3%B4n%20An%20Th%C3%A1i%2C%20ph%C6%B0%E1%BB%9Dng%20B%C3%ACnh%20%C4%90%E1%BB%8Bnh%2C%20t%E1%BB%89nh%20Gia%20Lai
A12: 11 | B12: 11 | C12: Văn hóa / du lịch / tâm linh | D12: Chùa Huệ Khánh | E12: Thôn An Thái, phường Bình Định, tỉnh Gia Lai | F12: Chưa có GPS số | G12: https://www.google.com/maps/search/?api=1&query_place_id=ChIJAR3qIuw9bzERD51dugj530Q | H12: https://www.google.com/maps/search/?api=1&query_place_id=ChIJAR3qIuw9bzERD51dugj530Q
A13: 12 | B13: 12 | C13: Văn hóa / du lịch / tâm linh | D13: Chùa Khánh Liên | E13: V4M8+VM9, Bình Định, Gia Lai | F13: Chưa có số điện thoại công khai | G13: https://www.google.com/maps/search/?api=1&query_place_id=ChIJz0OFATU_bzERgICoBQcHsoA | H13: https://www.google.com/maps/search/?api=1&query_place_id=ChIJz0OFATU_bzERgICoBQcHsoA
... A141: 140 | B141: 165 | C141: Giáo dục | D141: Trường Trung cấp Kinh tế Kỹ thuật Bình Định | E141: 27 Trần Thị Kỷ, phường Bình Định, tỉnh Gia Lai | F141: Chưa có GPS số; Chưa có số điện thoại công khai | G141: https://www.google.com/maps/search/?api=1&query=Tr%C6%B0%E1%BB%9Dng%20Trung%20c%E1%BA%A5p%20Kinh%20t%E1%BA%BF%20K%E1%BB%B9%20thu%E1%BA%ADt%20B%C3%ACnh%20%C4%90%E1%BB%8Bnh%2C%2027%20Tr%E1%BA%A7n%20Th%E1%BB%8B%20K%E1%BB%B7%2C%20ph%C6%B0%E1%BB%9Dng%20B%C3%ACnh%20%C4%90%E1%BB%8Bnh%2C%20t%E1%BB%89nh%20Gia%20Lai | H141: https://www.google.com/maps/search/?api=1&query=Tr%C6%B0%E1%BB%9Dng%20Trung%20c%E1%BA%A5p%20Kinh%20t%E1%BA%BF%20K%E1%BB%B9%20thu%E1%BA%ADt%20B%C3%ACnh%20%C4%90%E1%BB%8Bnh%2C%2027%20Tr%E1%BA%A7n%20Th%E1%BB%8B%20K%E1%BB%B7%2C%20ph%C6%B0%E1%BB%9Dng%20B%C3%ACnh%20%C4%90%E1%BB%8Bnh%2C%20t%E1%BB%89nh%20Gia%20Lai
